Workbook

Sheet Contents
A1: Supplementary Tables S1-S15 — strict-16 release ncbi-phylum-2026-08-04-v1
A3: Sheet | B3: Table
A4: S1 | B4: Supplementary Table S1
A5: S2 | B5: Supplementary Table S2
A6: S3 | B6: Supplementary Table S3
A7: S4 | B7: Supplementary Table S4
A8: S5 | B8: Supplementary Table S5
A9: S6 | B9: Supplementary Table S6
A10: S7 | B10: Supplementary Table S7
A11: S8 | B11: Supplementary Table S8
A12: S9 | B12: Supplementary Table S9
A13: S10 | B13: Supplementary Table S10
A14: S11 | B14: Supplementary Table S11
... A18: S15 | B18: Supplementary Table S15

Sheet S1_Notes
A1: Supplementary Table S1. Per-sample and per-phylum inventory (strict release)
A3: Taxonomy release: ncbi-phylum-2026-08-04-v1 (locked). Phylum and kingdom are taken from that release; the labels as submitted are retained alongside so every change is auditable.
A4: Rows: 169 carried over from the submitted workbook plus 6 added from the release = 176. NOTE: OE25F3POS.mzML appears twice in the submitted workbook (2 rows share that identity), so its stated count of 170 biological samples is 169 unique samples.
A5: 6 core-candidate samples of the release are ABSENT from the submitted inventory and have been added here, flagged in the 'Row source' column: ACNeffE25-123POS (Discosea, Acanthamoeba), Lu19POS (Cyanobacteriota, lichen), OE11-3-E4-P27POS (Streptophyta, Ginkgo), OE21-4-F3POS (Ascomycota, Tuber), OE25102891POS (Actinomycetota, Arthrobacter), OE25DSM1988POS (Ascomycota, Aspergillus). Culture-condition fields are unavailable for them. Without these rows S1b would disagree with the release and with Supplementary Figure 7.
A6: Phylum label changed for 52 of 176 rows.
A8: Relabelling applied (release authority, not edited here): Amoebozoa split to Discosea / Evosea; Euryarchaeota and Halobacteriota to Methanobacteriota; Crenarchaeota to Thermoproteota; Bryophyta, Marchantiophyta, Tracheophyta, Magnoliophyta and Charophyta to Streptophyta; Mortierellomycota separated from Mucoromycota.
A10: Kingdom uses the locked policy's ecological_group naming (Viridiplantae, Protists), which differs from the submitted table's Plantae / Protozoa. Ecological groups are display summaries and are never analysis units.
A12: Counts: 19 collection phyla; 16 analysis phyla (n>=2 in both polarities). Below threshold: Cercozoa, Cyanobacteriota, Mortierellomycota.
A13: Taxonomy scope: core_candidate rows have a valid NCBI phylum ancestor. descriptive_only rows (Bicosoecida, Rootnodules, Mixed) and viral samples are retained in the inventory but excluded from phylum inference, per policy.
A15: The submitted per-phylum n_species column is NOT reproduced. It is not derivable from any metadata column present and is internally inconsistent (for example Euryarchaeota was published as 4 species across 9 distinct genera). S1b therefore reports distinct genera, the finest rank the metadata determines for every sample - the same decision taken for Supplementary Figure 7.
A17: Scope: positive mode, matching the submitted table. The release also covers 195 negative-mode core samples.
A19: Producer: paper2_repro/scripts/build_table_s1_strict16.py

Sheet S1_Per_sample_inventory
A1: Supplementary Table S1a. Per-sample inventory (175 unique biological samples, 176 rows as submitted)
A2: Phylum and kingdom from the locked release; submitted labels retained.
A4: GNPS Filename | B4: Original Code | C4: FBMN_Batch | D4: Kingdom (release) | E4: Phylum (release) | F4: NCBI phylum taxid | G4: Taxonomy scope | H4: Kingdom (as submitted) | I4: Phylum (as submitted) | J4: Label changed | K4: Class | L4: Order | M4: Family | N4: Genus | O4: Species | P4: NCBI ID | Q4: KEGG ID | R4: Lipid Recovery % | S4: Media_DSMZ_or_type | T4: Temperature_C | U4: Oxygen_conditions | V4: pH | W4: Taxonomy release | X4: Row source | Y4: Count in summary
A5: Rhodococcus_Sp_OE11-3-E4-A1POS.mzML | B5: OE11-3-E4-A1POS | C5: batch_01_OE11-3-POS | D5: Bacteria | E5: Actinomycetota | F5: 201174 | G5: core_candidate | H5: Bacteria | I5: Actinomycetota | K5: Actinomycetia | L5: Mycobacteriales | M5: Nocardiaceae | N5: Rhodococcus | O5: unclassified | P5: 1827 | Q5: rqi | R5: 0 | W5: ncbi-phylum-2026-08-04-v1 | X5: submitted table | Y5: yes
A6: Haloferax_Volcanii_WR_340_OE11-3-E4-A4POS.mzML | B6: OE11-3-E4-A4POS | C6: batch_01_OE11-3-POS | D6: Archaea | E6: Methanobacteriota | F6: 28890 | G6: core_candidate | H6: Archaea | I6: Euryarchaeota | J6: yes | K6: Halobacteria | L6: Halobacteriales | M6: Halobacteriaceae | N6: Haloferax | O6: Haloferax volcanii | P6: 2246 | Q6: hvo | R6: 0 | T6: 37 | U6: aerobic | V6: 7.2 | W6: ncbi-phylum-2026-08-04-v1 | X6: submitted table | Y6: yes
A7: Arthrobacter_Sp_102891_OE11-3-E4-B5POS.mzML | B7: OE11-3-E4-B5POS | C7: batch_01_OE11-3-POS | D7: Bacteria | E7: Actinomycetota | F7: 201174 | G7: core_candidate | H7: Bacteria | I7: Actinomycetota | K7: Actinobacteridae | L7: Actinomycetales | M7: Micrococcaceae | N7: Arthrobacter | O7: unclassified | P7: 1663 | R7: 0 | W7: ncbi-phylum-2026-08-04-v1 | X7: submitted table | Y7: yes
A8: Rhizopus_Oligosporus_OE11-3-E4-F6POS.mzML | B8: OE11-3-E4-F6POS | C8: batch_01_OE11-3-POS | D8: Fungi | E8: Mucoromycota | F8: 1913637 | G8: core_candidate | H8: Fungi | I8: Mucoromycota | K8: Mucoromycetes | L8: Mucorales | M8: Rhizopodaceae | N8: Rhizopus | O8: Rhizopus Oligosporus | P8: 4847 | R8: 0 | S8: N/A - fruiting body | W8: ncbi-phylum-2026-08-04-v1 | X8: submitted table | Y8: yes
A9: Petroselinum_Crispum_(leaves)_OE11-3-E4-P18POS.mzML | B9: OE11-3-E4-P18POS | C9: batch_01_OE11-3-POS | D9: Viridiplantae | E9: Streptophyta | F9: 35493 | G9: core_candidate | H9: Plantae | I9: Trachaeophyta | J9: yes | K9: Magnoliopsida | L9: Apiales | M9: Apiaceae | N9: Petroelinum | O9: Petroselinum crispum (leaves) | P9: 4043 | R9: 0 | S9: N/A - field collected | W9: ncbi-phylum-2026-08-04-v1 | X9: submitted table | Y9: yes
A10: Ginko_biloba_OE11-3-E4-P27POS.mzML | B10: 27POS | C10: batch_01_OE11-3-POS | G10: excluded | H10: Plantae | I10: Trachaeophyta | J10: yes | K10: Ginkgoopsida | L10: Ginkgoales | M10: Ginkgoaceae | N10: Ginkgo | O10: Ginkgo biloba | P10: 3311 | R10: 0 | S10: N/A - field collected | W10: ncbi-phylum-2026-08-04-v1 | X10: submitted table | Y10: no
A11: Methanosarcina_Spelaei_OE11-E4-A7POS.mzML | B11: OE11-E4-A7POS | C11: batch_01_OE11-3-POS | D11: Archaea | E11: Methanobacteriota | F11: 28890 | G11: core_candidate | H11: Archaea | I11: Methanobacteriota | K11: Methanomicrobia | L11: Methanosarcinales | M11: Methanosarcinaceae | N11: Methanosarcina | O11: Methanosarcina spelaei | P11: 1609969 | Q11: mma | R11: 0 | S11: 120a | T11: 33 | U11: anaerobic | V11: 6.5 | W11: ncbi-phylum-2026-08-04-v1 | X11: submitted table | Y11: yes
A12: Methanopyrus_Kandleri_OE11-E4-B3POS.mzML | B12: OE11-E4-B3POS | C12: batch_01_OE11-3-POS | D12: Archaea | E12: Methanobacteriota | F12: 28890 | G12: core_candidate | H12: Archaea | I12: Euryarchaeota | J12: yes | K12: Methanopyri | L12: Methanopyrales | M12: Methanopyraceae | N12: Methanopyrus | O12: Methanopyrus kandleri | P12: 2320 | Q12: mka | R12: 0 | S12: 511 | T12: 98 | U12: anaerobic | W12: ncbi-phylum-2026-08-04-v1 | X12: submitted table | Y12: yes
A13: Streptosporangium_Roseum_OE11-E4-B4POS.mzML | B13: OE11-E4-B4POS | C13: batch_01_OE11-3-POS | D13: Bacteria | E13: Actinomycetota | F13: 201174 | G13: core_candidate | H13: Bacteria | I13: Actinomycetota | K13: Actinobacteridae | L13: Actinomycetales | M13: Streptosporangiaceae | N13: Streptosporangium | O13: Streptosporangium roseum | P13: 1928 | R13: 0 | S13: 84 | T13: 28 | U13: aerobic | V13: 7.2 | W13: ncbi-phylum-2026-08-04-v1 | X13: submitted table | Y13: yes
A14: Amanita_Caesarea_OE11-E4-F15POS.mzML | B14: OE11-E4-F15POS | C14: batch_01_OE11-3-POS | D14: Fungi | E14: Basidiomycota | F14: 5204 | G14: core_candidate | H14: Fungi | I14: Basidiomycota | K14: Agaricomycetes | L14: Agaricales | M14: Amanitaceae | N14: Amanita | O14: Amanita caserea | P14: 67695 | R14: 0 | S14: N/A - fruiting body | W14: ncbi-phylum-2026-08-04-v1 | X14: submitted table | Y14: yes
A15: Trichoderma_Flavofuscum_OE11-E4-F2POS.mzML | B15: OE11-E4-F2POS | C15: batch_01_OE11-3-POS | D15: Fungi | E15: Ascomycota | F15: 4890 | G15: core_candidate | H15: Fungi | I15: Ascomycota | K15: Sordariomycetes | L15: Hypocreales | M15: Hypocreaceae | N15: Gliocladium | O15: Gliocladium flavofuscum | P15: 29875 | Q15: tre | R15: 0 | W15: ncbi-phylum-2026-08-04-v1 | X15: submitted table | Y15: yes
A16: Mucor_Hiemalis_INF1507_17_OE11-E4-F47POS.mzML | B16: OE11-E4-F47POS | C16: batch_01_OE11-3-POS | D16: Fungi | E16: Mucoromycota | F16: 1913637 | G16: core_candidate | H16: Fungi | I16: Mucoromycota | K16: Mucoromycetes | L16: Mucorales | M16: Mucoraceae | N16: Mucor | O16: Mucor hiemalis | P16: 64493 | R16: 0 | S16: MEB | T16: 22 | U16: aerobic | V16: 5.6 | W16: ncbi-phylum-2026-08-04-v1 | X16: submitted table | Y16: yes
A17: Equisetum_Arvense_OE11-E4-P11POS.mzML | B17: OE11-E4-P11POS | C17: batch_01_OE11-3-POS | D17: Viridiplantae | E17: Streptophyta | F17: 35493 | G17: core_candidate | H17: Plantae | I17: Trachaeophyta | J17: yes | K17: Polypodiopsida | L17: Equisetales | M17: Equisetaceae | N17: Equisetum | O17: Equisetum arvense | P17: 3258 | R17: 0 | S17: N/A - field collected | W17: ncbi-phylum-2026-08-04-v1 | X17: submitted table | Y17: yes
A18: Allium_Ursinum_OE11-E4-P14POS.mzML | B18: OE11-E4-P14POS | C18: batch_01_OE11-3-POS | D18: Viridiplantae | E18: Streptophyta | F18: 35493 | G18: core_candidate | H18: Plantae | I18: Trachaeophyta | J18: yes | K18: Liliopsida | L18: Asparagales | M18: Amaryllidaceae | N18: Allium | O18: Allium ursinum | P18: 4684 | R18: 0 | S18: N/A - field collected | W18: ncbi-phylum-2026-08-04-v1 | X18: submitted table | Y18: yes
A19: Taraxacum_officinale (roots)_OE11-E4-P26POS.mzML | B19: OE11-E4-P26POS | C19: batch_01_OE11-3-POS | D19: Viridiplantae | E19: Streptophyta | F19: 35493 | G19: core_candidate | H19: Plantae | I19: Trachaeophyta | J19: yes | K19: Magnoliopsida | L19: Asterales | M19: Asteraceae | N19: Taraxcum | O19: Taraxacum officinale (roots) | P19: 50225 | R19: 0 | S19: N/A - field collected | W19: ncbi-phylum-2026-08-04-v1 | X19: submitted table | Y19: yes
A20: Priestia_Aryabhattai_B8W22_OE21-4-11POS.mzML | B20: OE21-4-11POS | C20: batch_02_OE21-4-POS | D20: Bacteria | E20: Bacillota | F20: 1239 | G20: core_candidate | H20: Bacteria | I20: Bacillota | K20: Bacilli | L20: Caryophanales | M20: Bacillaceae | N20: Priestia | O20: Priestia aryabhattai | P20: 412384 | Q20: bsu | R20: 0 | W20: ncbi-phylum-2026-08-04-v1 | X20: submitted table | Y20: yes
A21: Exiguobacterium_Aestuarii_OE21-4-19POS.mzML | B21: OE21-4-19POS | C21: batch_02_OE21-4-POS | D21: Bacteria | E21: Bacillota | F21: 1239 | G21: core_candidate | H21: Bacteria | I21: Bacillota | K21: Bacilli | L21: Bacillales | M21: Bacillaceae | N21: Exiguobacterium | O21: Exiguobacterium aestuarii | P21: 273527 | Q21: esi | R21: 0 | W21: ncbi-phylum-2026-08-04-v1 | X21: submitted table | Y21: yes
A22: Bacillus_Proteolyticus_OE21-4-28POS.mzML | B22: OE21-4-28POS | C22: batch_02_OE21-4-POS | D22: Bacteria | E22: Bacillota | F22: 1239 | G22: core_candidate | H22: Bacteria | I22: Bacillota | K22: Bacilli | L22: Caryophanales | M22: Bacillaceae | N22: Bacillus | O22: Bacillus proteolyticus | P22: 2026192 | Q22: bsu | R22: 0 | W22: ncbi-phylum-2026-08-04-v1 | X22: submitted table | Y22: yes
A23: Paribacillus_Frigoritolerans_OE21-4-31POS.mzML | B23: OE21-4-31POS | C23: batch_02_OE21-4-POS | D23: Bacteria | E23: Bacillota | F23: 1239 | G23: core_candidate | H23: Bacteria | I23: Bacillota | K23: Bacilli | L23: Caryophanales | M23: Bacillaceae | N23: Peribacillus | O23: Peribacillus frigoritolerans | P23: 450367 | R23: 0 | W23: ncbi-phylum-2026-08-04-v1 | X23: submitted table | Y23: yes
A24: Priestia_Megaterium_OE21-4-34POS.mzML | B24: OE21-4-34POS | C24: batch_02_OE21-4-POS | D24: Bacteria | E24: Bacillota | F24: 1239 | G24: core_candidate | H24: Bacteria | I24: Bacillota | K24: Bacilli | L24: Caryophanales | M24: Bacillaceae | N24: Priestia | O24: Priestia megaterium | P24: 1404 | Q24: bsu | R24: 0 | W24: ncbi-phylum-2026-08-04-v1 | X24: submitted table | Y24: yes
A25: Methanocaldococcus_Jannaschii_OE21-4-A10POS.mzML | B25: OE21-4-A10POS | C25: batch_02_OE21-4-POS | D25: Archaea | E25: Methanobacteriota | F25: 28890 | G25: core_candidate | H25: Archaea | I25: Euryarchaeota | J25: yes | K25: Methanococci | L25: Methanococcales | M25: Methanocaldococcaceae | N25: Methanocaldococcus | O25: Methanocaldococcus jannaschii | P25: 2190 | Q25: mja | R25: 5033 | S25: 282 | T25: 80 | U25: anaerobic | W25: ncbi-phylum-2026-08-04-v1 | X25: submitted table | Y25: yes
A26: Methanospirillum_Stamsii_OE21-4-A12POS.mzML | B26: OE21-4-A12POS | C26: batch_02_OE21-4-POS | D26: Archaea | E26: Methanobacteriota | F26: 28890 | G26: core_candidate | H26: Archaea | I26: Methanobacteriota | K26: Methanomicrobia | L26: Methanomicrobiales | M26: Methanospirillaceae | N26: Methanospirillum | O26: Methanospirillum stamsii | P26: 2222 | Q26: mhu | R26: 4830.02 | S26: 119 | T26: 29 | U26: anaerobic | V26: 7 | W26: ncbi-phylum-2026-08-04-v1 | X26: submitted table | Y26: yes
A27: Sulfolobus_Islandicus_OE21-4-A1POS.mzML | B27: OE21-4-A1POS | C27: batch_02_OE21-4-POS | D27: Archaea | E27: Thermoproteota | F27: 28889 | G27: core_candidate | H27: Archaea | I27: Thermoproteota | K27: Thermoprotei | L27: Sulfolobales | M27: Sulfolobaceae | N27: Sulfolobus | O27: Sulfolobus islandicus | P27: 43080 | Q27: sai | R27: 5707.28 | S27: 182 | T27: 75 | U27: aerobic | V27: 3 | W27: ncbi-phylum-2026-08-04-v1 | X27: submitted table | Y27: yes
A28: Sulfolobus_Islandicus_OE21-4-A1POS_20240618215255.mzML | B28: OE21-4-A1POS_20240618215255 | C28: batch_02_OE21-4-POS | D28: Archaea | E28: Thermoproteota | F28: 28889 | G28: core_candidate | H28: Archaea | I28: Thermoproteota | K28: Thermoprotei | L28: Sulfolobales | M28: Sulfolobaceae | N28: Sulfolobus | O28: Sulfolobus islandicus | P28: 43080 | Q28: sai | R28: 5707.28 | S28: 182 | T28: 75 | U28: aerobic | V28: 3 | W28: ncbi-phylum-2026-08-04-v1 | X28: submitted table | Y28: yes
A29: Sulfolobus_Acidocaldarius_OE21-4-A3POS.mzML | B29: OE21-4-A3POS | C29: batch_02_OE21-4-POS | D29: Archaea | E29: Thermoproteota | F29: 28889 | G29: core_candidate | H29: Archaea | I29: Crenarchaeota | J29: yes | K29: Thermoprotei | L29: Sulfolobales | M29: Sulfolobaceae | N29: Sulfolobus | O29: Sulfolobus acidocaldarius | P29: 2285 | Q29: sso | R29: 4848.22 | S29: 88 | T29: 75 | U29: aerobic | V29: 3 | W29: ncbi-phylum-2026-08-04-v1 | X29: submitted table | Y29: yes
A30: Methanothermococcus_Okinawensis_OE21-4-A5POS.mzML | B30: OE21-4-A5POS | C30: batch_02_OE21-4-POS | D30: Archaea | E30: Methanobacteriota | F30: 28890 | G30: core_candidate | H30: Archaea | I30: Euryarchaeota | J30: yes | K30: Methanococci | L30: Methanococcales | M30: Methanococcaceae� | N30: Methanothermococcus | O30: Methanothermococcus okinawensis | P30: 155863 | Q30: mok | R30: 4658.34 | S30: 282 | T30: 65 | U30: anaerobic | W30: ncbi-phylum-2026-08-04-v1 | X30: submitted table | Y30: yes
A31: Methanotorris_Igneus_OE21-4-A6POS.mzML | B31: OE21-4-A6POS | C31: batch_02_OE21-4-POS | D31: Archaea | E31: Methanobacteriota | F31: 28890 | G31: core_candidate | H31: Archaea | I31: Euryarchaeota | J31: yes | K31: Methanococci | L31: Methanococcales | M31: Methanocaldococcaceae | N31: Methanotorris | O31: Methanotorris igneus | P31: 647113 | Q31: mig | R31: 4793.77 | S31: 282 | T31: 85 | U31: anaerobic | W31: ncbi-phylum-2026-08-04-v1 | X31: submitted table | Y31: yes
A32: Haloferax_Volcanii_WR_340_OE21-4-A9POS.mzML | B32: OE21-4-A9POS | C32: batch_02_OE21-4-POS | D32: Archaea | E32: Methanobacteriota | F32: 28890 | G32: core_candidate | H32: Archaea | I32: Euryarchaeota | J32: yes | K32: Halobacteria | L32: Halobacteriales | M32: Halobacteriaceae | N32: Haloferax | O32: Haloferax volcanii | P32: 2246 | Q32: hvo | R32: 4797.5 | T32: 37 | U32: aerobic | V32: 7.2 | W32: ncbi-phylum-2026-08-04-v1 | X32: submitted table | Y32: yes
A33: Streptosporangium_Roseum_OE21-4-B9POS.mzML | B33: OE21-4-B9POS | C33: batch_02_OE21-4-POS | D33: Bacteria | E33: Actinomycetota | F33: 201174 | G33: core_candidate | H33: Bacteria | I33: Actinomycetota | K33: Actinobacteridae | L33: Actinomycetales | M33: Streptosporangiaceae | N33: Streptosporangium | O33: Streptosporangium roseum | P33: 1928 | R33: 0 | S33: 84 | T33: 28 | U33: aerobic | V33: 7.2 | W33: ncbi-phylum-2026-08-04-v1 | X33: submitted table | Y33: yes
A34: Streptomyces_Sp_OE21-4-E6C13POS.mzML | B34: OE21-4-E6C13POS | C34: batch_02_OE21-4-POS | D34: Bacteria | E34: Actinomycetota | F34: 201174 | G34: core_candidate | H34: Bacteria | I34: Actinomycetota | K34: Actinobacteridae | L34: Actinomycetales | M34: Streptomycataceae | N34: Stretomyces | O34: unclassified | P34: 1883 | Q34: sco | R34: 0 | W34: ncbi-phylum-2026-08-04-v1 | X34: submitted table | Y34: yes
A35: Rhodococcus_Sp_OE21-4-E6C21POS.mzML | B35: OE21-4-E6C21POS | C35: batch_02_OE21-4-POS | D35: Bacteria | E35: Actinomycetota | F35: 201174 | G35: core_candidate | H35: Bacteria | I35: Actinomycetota | K35: Actinomycetia | L35: Mycobacteriales | M35: Nocardiaceae | N35: Rhodococcus | O35: unclassified | P35: 1827 | Q35: rqi | R35: 0 | W35: ncbi-phylum-2026-08-04-v1 | X35: submitted table | Y35: yes
A36: Rhodococcus_Sp_OE21-4-E6C4POS.mzML | B36: OE21-4-E6C4POS | C36: batch_02_OE21-4-POS | D36: Bacteria | E36: Actinomycetota | F36: 201174 | G36: core_candidate | H36: Bacteria | I36: Actinomycetota | K36: Actinomycetia | L36: Mycobacteriales | M36: Nocardiaceae | N36: Rhodococcus | O36: unclassified | P36: 1827 | Q36: rqi | R36: 0 | W36: ncbi-phylum-2026-08-04-v1 | X36: submitted table | Y36: yes
A37: Rhodococcus_Sp_OE21-4-E6C6POS.mzML | B37: OE21-4-E6C6POS | C37: batch_02_OE21-4-POS | D37: Bacteria | E37: Actinomycetota | F37: 201174 | G37: core_candidate | H37: Bacteria | I37: Actinomycetota | K37: Actinomycetia | L37: Mycobacteriales | M37: Nocardiaceae | N37: Rhodococcus | O37: unclassified | P37: 1827 | Q37: rqi | R37: 0 | W37: ncbi-phylum-2026-08-04-v1 | X37: submitted table | Y37: yes
A38: Aspergillus_nidulans_HBs_F02_OE21-4-E8F38POS.mzML | B38: OE21-4-E8F38POS | C38: batch_02_OE21-4-POS | D38: Fungi | E38: Ascomycota | F38: 4890 | G38: core_candidate | H38: Fungi | I38: Ascomycota | K38: Eurotiomycetes | L38: Eurotiales | M38: Aspergillaceae | N38: Aspergillus | O38: Aspergillus nidulans | P38: 162425 | Q38: afm | R38: 0 | S38: MEB | T38: 22 | U38: aerobic | V38: 5.6 | W38: ncbi-phylum-2026-08-04-v1 | X38: submitted table | Y38: yes
A39: Gibellulopsis_Nigrescens_NG_p09_OE21-4-E8F41POS.mzML | B39: OE21-4-E8F41POS | C39: batch_02_OE21-4-POS | D39: Fungi | E39: Ascomycota | F39: 4890 | G39: core_candidate | H39: Fungi | I39: Ascomycota | K39: Sordariomycetes | L39: Glomerellales | M39: Plectosphaerellaceae | N39: Gibellulopsis | O39: Gibellulopsis nigrescens | P39: 796325 | S39: MEB | T39: 22 | U39: aerobic | V39: 5.6 | W39: ncbi-phylum-2026-08-04-v1 | X39: submitted table | Y39: yes
A40: Warcupia_Sp_D_D17_OE21-4-E8F42POS.mzML | B40: OE21-4-E8F42POS | C40: batch_02_OE21-4-POS | D40: Fungi | E40: Ascomycota | F40: 4890 | G40: core_candidate | H40: Fungi | I40: Ascomycota | K40: Pezizomycetes | L40: Pezizales | M40: Otideaceae | N40: Warcupia | O40: unclassified | P40: 277197 | W40: ncbi-phylum-2026-08-04-v1 | X40: submitted table | Y40: yes
A41: Exophiala_Sp_DG1901_E_OE21-4-E8F44POS.mzML | B41: OE21-4-E8F44POS | C41: batch_02_OE21-4-POS | D41: Fungi | E41: Ascomycota | F41: 4890 | G41: core_candidate | H41: Fungi | I41: Ascomycota | K41: Chaetothyriomycetes | L41: Chaetothyriales | M41: Herpotrichiellaceae | N41: Exophiala | O41: unclassified | P41: 5980 | W41: ncbi-phylum-2026-08-04-v1 | X41: submitted table | Y41: yes
...

Sheet S1_Per_phylum_summary
A1: Supplementary Table S1b. Per-phylum inventory (core samples)
A2: Sample and genus counts per release phylum. n_species is not reported - see Notes.
A4: Kingdom (release) | B4: Phylum (release) | C4: n_samples | D4: n_genera | E4: In strict analysis set
A5: Animalia | B5: Arthropoda | C5: =COUNTIFS(Per_sample_inventory!$E$5:$E$180,B5,Per_sample_inventory!$Y$5:$Y$180,"yes") | D5: 8 | E5: yes
A6: Animalia | B6: Mollusca | C6: =COUNTIFS(Per_sample_inventory!$E$5:$E$180,B6,Per_sample_inventory!$Y$5:$Y$180,"yes") | D6: 1 | E6: yes
A7: Animalia | B7: Nematoda | C7: =COUNTIFS(Per_sample_inventory!$E$5:$E$180,B7,Per_sample_inventory!$Y$5:$Y$180,"yes") | D7: 2 | E7: yes
A8: Archaea | B8: Methanobacteriota | C8: =COUNTIFS(Per_sample_inventory!$E$5:$E$180,B8,Per_sample_inventory!$Y$5:$Y$180,"yes") | D8: 9 | E8: yes
A9: Archaea | B9: Thermoproteota | C9: =COUNTIFS(Per_sample_inventory!$E$5:$E$180,B9,Per_sample_inventory!$Y$5:$Y$180,"yes") | D9: 1 | E9: yes
A10: Bacteria | B10: Actinomycetota | C10: =COUNTIFS(Per_sample_inventory!$E$5:$E$180,B10,Per_sample_inventory!$Y$5:$Y$180,"yes") | D10: 6 | E10: yes
A11: Bacteria | B11: Bacillota | C11: =COUNTIFS(Per_sample_inventory!$E$5:$E$180,B11,Per_sample_inventory!$Y$5:$Y$180,"yes") | D11: 7 | E11: yes
A12: Bacteria | B12: Cyanobacteriota | C12: =COUNTIFS(Per_sample_inventory!$E$5:$E$180,B12,Per_sample_inventory!$Y$5:$Y$180,"yes") | D12: 2 | E12: no (n<2)
A13: Bacteria | B13: Pseudomonadota | C13: =COUNTIFS(Per_sample_inventory!$E$5:$E$180,B13,Per_sample_inventory!$Y$5:$Y$180,"yes") | D13: 4 | E13: yes
A14: Fungi | B14: Ascomycota | C14: =COUNTIFS(Per_sample_inventory!$E$5:$E$180,B14,Per_sample_inventory!$Y$5:$Y$180,"yes") | D14: 22 | E14: yes
A15: Fungi | B15: Basidiomycota | C15: =COUNTIFS(Per_sample_inventory!$E$5:$E$180,B15,Per_sample_inventory!$Y$5:$Y$180,"yes") | D15: 9 | E15: yes
A16: Fungi | B16: Mortierellomycota | C16: =COUNTIFS(Per_sample_inventory!$E$5:$E$180,B16,Per_sample_inventory!$Y$5:$Y$180,"yes") | D16: 1 | E16: no (n<2)
... A23: Viridiplantae | B23: Streptophyta | C23: =COUNTIFS(Per_sample_inventory!$E$5:$E$180,B23,Per_sample_inventory!$Y$5:$Y$180,"yes") | D23: 14 | E23: yes
A25: n_samples is a live COUNTIFS against S1a. n_genera is computed from the Genus column (first token, case-normalised) and written as a value - a distinct count has no formula form that evaluates reliably outside Excel.

Sheet S2_Notes
A1: Supplementary Table S2. FBMN batch composition (strict release)
A3: Per-batch sample counts, feature counts, organism composition and GNPS2 task IDs. Positive mode.
A5: Feature counts are unchanged from the submitted table and were reproduced exactly from the FBMN quantification tables (total 338,878).
A7: Sample counts were approximations in the submitted table ("~20" ... total "~205"). They are now exact. Two columns are given because the approximations conflated them: all injections assigned to the batch, and biological samples with a valid NCBI phylum ancestor (168 across the six batches).
A9: The submitted "Primary kingdoms" column mixed taxonomic ranks and used retired labels - Bryophyta, Cyanobacteria, Amoebozoa, and the phyla Bacillota and Actinomycetota listed as kingdoms. It is replaced by two rank-explicit columns taken from the locked release. Organism groups are display summaries; phyla are the analysis units.
A11: Batch-organism confounding, restated on the strict labels:
A12: Animalia is confined to a single batch: all 17 animal samples are in batch_03_OE23-POS.
A13: Protists occur in only two batches: batch_05_OE25-1-ALL (12), batch_04_OE26-1POS (6).
A14: batch_06_ALL-25-2 is taxonomically homogeneous: Bacteria 27 - it contains no eukaryotes at all.
A15: Viral samples (n=2) were acquired in batch 06 but are excluded from the study scope by author instruction, so they do not appear in the counts above.
A17: Sheet 'Batch_by_phylum' gives the full batch x phylum matrix so the confounding can be assessed directly.
A19: Taxonomy release: ncbi-phylum-2026-08-04-v1 (locked). Producer: paper2_repro/scripts/build_table_s2_strict16.py

Sheet S2_Table
A1: Supplementary Table S2. FBMN batch composition
A2: Sample counts exact; feature counts reproduced from the quantification tables.
A4: Batch | B4: Name | C4: Samples (all injections) | D4: Samples (biological) | E4: Features | F4: Organism groups (n) | G4: Phyla, strict release (n) | H4: GNPS2 task ID
A5: 01 | B5: OE11-3-POS | C5: 18 | D5: 15 | E5: 40936 | F5: Viridiplantae 5, Fungi 4, Archaea 3, Bacteria 3 | G5: Streptophyta 5, Actinomycetota 3, Methanobacteriota 3, Mucoromycota 2, Basidiomycota 1, Ascomycota 1 | H5: 57a91e57a53f4ab7ac5ccd69fbab2c4e
A6: 02 | B6: OE21-4-POS | C6: 53 | D6: 40 | E6: 84347 | F6: Fungi 15, Bacteria 10, Archaea 8, Viridiplantae 7 | G6: Ascomycota 9, Streptophyta 7, Basidiomycota 6, Bacillota 5, Methanobacteriota 5, Actinomycetota 5, Thermoproteota 3 | H6: 8e0f0e314b814193b42bbcca4af86982
A7: 03 | B7: OE23-POS | C7: 28 | D7: 26 | E7: 89731 | F7: Animalia 17, Viridiplantae 7, Bacteria 2 | G7: Arthropoda 11, Chlorophyta 5, Nematoda 4, Mollusca 2, Cyanobacteriota 2, Streptophyta 2 | H7: bb4fd387ab584c32bae96e74a00b0b08
A8: 04 | B8: OE26-1POS | C8: 48 | D8: 44 | E8: 43206 | F8: Fungi 26, Archaea 8, Protists 6, Bacteria 4 | G8: Ascomycota 17, Methanobacteriota 8, Mucoromycota 5, Discosea 4, Basidiomycota 3, Pseudomonadota 3, Actinomycetota 1, Mortierellomycota 1, Heterolobosea 1, Cercozoa 1 | H8: 26e41456c73f457cbfd6d471b207f37a
A9: 05 | B9: OE25-1-ALL | C9: 18 | D9: 16 | E9: 20424 | F9: Protists 12, Bacteria 4 | G9: Evosea 5, Heterolobosea 4, Discosea 3, Pseudomonadota 3, Bacillota 1 | H9: 5f9c17db47c94bcda93ea3cd12ac1b64
A10: 06 | B10: ALL-25-2-POS | C10: 54 | D10: 27 | E10: 60234 | F10: Bacteria 27 | G10: Bacillota 19, Actinomycetota 6, Pseudomonadota 2 | H10: 9f8b16574b08468f88acf4eca84d2805
A11: Total | C11: =SUM(C5:C10) | D11: =SUM(D5:D10) | E11: =SUM(E5:E10)

Sheet S2_Batch_by_phylum
A1: Supplementary Table S2b. Batch x phylum matrix (biological samples)
A2: Counts of core-candidate samples per strict phylum.
A4: Batch | B4: Actinomycetota | C4: Arthropoda | D4: Ascomycota | E4: Bacillota | F4: Basidiomycota | G4: Cercozoa | H4: Chlorophyta | I4: Cyanobacteriota | J4: Discosea | K4: Evosea | L4: Heterolobosea | M4: Methanobacteriota | N4: Mollusca | O4: Mortierellomycota | P4: Mucoromycota | Q4: Nematoda | R4: Pseudomonadota | S4: Streptophyta | T4: Thermoproteota
A5: batch_01_OE11-3-POS | B5: 3 | C5: 0 | D5: 1 | E5: 0 | F5: 1 | G5: 0 | H5: 0 | I5: 0 | J5: 0 | K5: 0 | L5: 0 | M5: 3 | N5: 0 | O5: 0 | P5: 2 | Q5: 0 | R5: 0 | S5: 5 | T5: 0
A6: batch_02_OE21-4-POS | B6: 5 | C6: 0 | D6: 9 | E6: 5 | F6: 6 | G6: 0 | H6: 0 | I6: 0 | J6: 0 | K6: 0 | L6: 0 | M6: 5 | N6: 0 | O6: 0 | P6: 0 | Q6: 0 | R6: 0 | S6: 7 | T6: 3
A7: batch_03_OE23-POS | B7: 0 | C7: 11 | D7: 0 | E7: 0 | F7: 0 | G7: 0 | H7: 5 | I7: 2 | J7: 0 | K7: 0 | L7: 0 | M7: 0 | N7: 2 | O7: 0 | P7: 0 | Q7: 4 | R7: 0 | S7: 2 | T7: 0
A8: batch_04_OE26-1POS | B8: 1 | C8: 0 | D8: 17 | E8: 0 | F8: 3 | G8: 1 | H8: 0 | I8: 0 | J8: 4 | K8: 0 | L8: 1 | M8: 8 | N8: 0 | O8: 1 | P8: 5 | Q8: 0 | R8: 3 | S8: 0 | T8: 0
A9: batch_05_OE25-1-ALL | B9: 0 | C9: 0 | D9: 0 | E9: 1 | F9: 0 | G9: 0 | H9: 0 | I9: 0 | J9: 3 | K9: 5 | L9: 4 | M9: 0 | N9: 0 | O9: 0 | P9: 0 | Q9: 0 | R9: 3 | S9: 0 | T9: 0
A10: batch_06_ALL-25-2 | B10: 6 | C10: 0 | D10: 0 | E10: 19 | F10: 0 | G10: 0 | H10: 0 | I10: 0 | J10: 0 | K10: 0 | L10: 0 | M10: 0 | N10: 0 | O10: 0 | P10: 0 | Q10: 0 | R10: 2 | S10: 0 | T10: 0

Sheet S3_Diagnostic_ion_database
A1: lipid_class | B1: type | C1: ion_name | D1: m_z_or_neutral_loss
A2: Phospholipid | B2: fragment | C2: Phosphocholine_C5H13NO4P | D2: 184.0733
A3: PE | B3: fragment | C3: Glycerophosphoethanolamine | D3: 196.038
A4: PG | B4: fragment | C4: Glycerophosphoglycerol | D4: 171.0058
A5: PG | B5: fragment | C5: Glycerophosphoglycerol-H2O | D5: 152.9953
A6: PI | B6: fragment | C6: Glycerophosphoinositol | D6: 241.0119
A7: Sphingolipid | B7: fragment | C7: Sphingoid_d18:1 | D7: 264.2686
A8: Sphingolipid | B8: fragment | C8: Sphingoid_d18:1+H2O | D8: 282.2791
A9: Sphingolipid | B9: fragment | C9: Sphingoid_d18:0 | D9: 252.2686
A10: Betaine_Lipid | B10: fragment | C10: DGTS_headgroup | D10: 236.1492
A11: Sterol | B11: fragment | C11: Cholesterol_-H2O | D11: 369.3516
A12: Sterol | B12: fragment | C12: Campesterol_-H2O | D12: 383.3672
... A51: Terpenoid | B51: terpenoid_fragment | C51: RDA_triterpene | D51: 218.2035

Sheet S3_Notes_and_provenance
A1: Supplementary Table S3 — corrected diagnostic MS/MS classifier
A3: Status | B3: Recovered reproducible source
A4: Total rules | B4: 50
A5: Diagnostic fragments | B5: 24
A6: Neutral losses | B6: 5
A7: Terpenoid fragments | B7: 21
A8: Classifier labels | B8: 13
A9: Unsupported prior claim | B9: 66 entries
A10: Missing from claimed set | B10: 16
A11: Authoritative source | B11: ms2_classify_indval.py
A12: Correction | B12: Replace the 66-entry claim with 50 diagnostic rules across 13 classifier labels.
A14: The recovered 33-entry quick-reference table is not the executable classifier. No standalone 66-entry source was found; the missing 16 entries were not inferred or fabricated.

Sheet S4_Notes
A1: Supplementary Table S4. Distance-metric sensitivity of the lipidome-phylogeny Mantel test (strict release)
A3: Mantel r between the phylum-level lipidome distance matrix and the phylogenetic distance matrix, over the 16 analysis phyla (120 pairs), in both ionisation modes.
A5: Bray-Curtis is used for all main analyses; Jaccard and cosine are reported to show the phylogenetic signal is not an artefact of the distance metric.
A7: STATUS: documented recomputation, not a reproduction. The published values were computed on the pre-correction unit scheme, and the phylogeny distance matrix for that scheme is not in the repository (only the 16-phylum matrix exists), so they cannot be recomputed. Consistency check: this code path gives Bray-Curtis r = 0.598 (POS) and 0.761 (NEG) against the published 0.603 and 0.767 - a shift below 0.01. Sheet 'Vs_submitted' places the two side by side.
A9: The submitted table reported Jaccard and cosine for positive mode only and left negative mode as em-dashes. Both are now computed.
A11: Jaccard is computed on presence/absence profiles, the standard for community data; Bray-Curtis and cosine on abundance profiles. The 'Profile basis' column in 'Full_results' records this per row.
A13: p values are permutation-based (label permutations of the phylogeny matrix), not the parametric correlation p. Method and permutation count are given per row in 'Full_results'.
A15: Machinery is Supplementary Figure 1d's, unchanged: same profile builder (cross-batch features, detection >= 5%, mean intensity >= 500), same permutation test, same seeds.
A17: Taxonomy release: ncbi-phylum-2026-08-04-v1 (locked). Producer: paper2_repro/scripts/build_table_s4_strict16.py

Sheet S4_Table
A1: Supplementary Table S4. Distance-metric sensitivity (Mantel r, strict release)
A2: Permutation p values. Negative mode now included for all three metrics.
A4: Distance metric | B4: POS Mantel r | C4: POS p-value | D4: NEG Mantel r | E4: NEG p-value
A5: Bray-Curtis | B5: 0.598 | C5: 0.0001 | D5: 0.761 | E5: 0.0001
A6: Jaccard | B6: 0.421 | C6: 0.0043 | D6: 0.517 | E6: 0.0017
A7: Cosine | B7: 0.452 | C7: 0.0001 | D7: 0.622 | E7: 0.0001

Sheet S4_Full_results
A1: Supplementary Table S4b. Full Mantel results
A2: Per metric and mode, with profile basis, pair counts and permutation method.
A4: Distance metric | B4: Profile basis | C4: Mode | D4: n phyla | E4: n pairs | F4: Mantel r | G4: Mantel p (permutation) | H4: Permutations | I4: Permutation method | J4: Seed
A5: Bray-Curtis | B5: abundance | C5: POS | D5: 16 | E5: 120 | F5: 0.598 | G5: 0.0001 | H5: 9999 | I5: random_9999_label_permutations | J5: 20720247
A6: Jaccard | B6: presence/absence | C6: POS | D6: 16 | E6: 120 | F6: 0.421 | G6: 0.0043 | H6: 9999 | I6: random_9999_label_permutations | J6: 20720247
A7: Cosine | B7: abundance | C7: POS | D7: 16 | E7: 120 | F7: 0.452 | G7: 0.0001 | H7: 9999 | I7: random_9999_label_permutations | J7: 20720247
A8: Bray-Curtis | B8: abundance | C8: NEG | D8: 16 | E8: 120 | F8: 0.761 | G8: 0.0001 | H8: 9999 | I8: random_9999_label_permutations | J8: 21211386
A9: Jaccard | B9: presence/absence | C9: NEG | D9: 16 | E9: 120 | F9: 0.517 | G9: 0.0017 | H9: 9999 | I9: random_9999_label_permutations | J9: 21211386
A10: Cosine | B10: abundance | C10: NEG | D10: 16 | E10: 120 | F10: 0.622 | G10: 0.0001 | H10: 9999 | I10: random_9999_label_permutations | J10: 21211386

Sheet S4_Vs_submitted
A1: Supplementary Table S4c. Strict release vs submitted
A2: Side-by-side. The submitted values are not reproducible - see Notes.
A4: Distance metric | B4: POS Mantel r | C4: POS p-value | D4: NEG Mantel r | E4: NEG p-value | F4: POS Mantel r (submitted) | G4: POS p-value (submitted) | H4: NEG Mantel r (submitted) | I4: NEG p-value (submitted)
A5: Bray-Curtis | B5: 0.598 | C5: 0.0001 | D5: 0.761 | E5: 0.0001 | F5: 0.603 | G5: <0.001 | H5: 0.767 | I5: <0.001
A6: Jaccard | B6: 0.421 | C6: 0.0043 | D6: 0.517 | E6: 0.0017 | F6: 0.361 | G6: <0.001 | H6: — | I6: —
A7: Cosine | B7: 0.452 | C7: 0.0001 | D7: 0.622 | E7: 0.0001 | F7: 0.396 | G7: <0.001 | H7: — | I7: —

Sheet S5_Notes
A1: Supplementary Table S5. Per-phylum biomarker counts by polarity and annotation tier (strict release)
A3: Positive mode: 11,371 biomarkers across 16 analysis phyla. Negative mode: 5,697 biomarkers across 16 phyla.
A5: Annotation tiers: Gold = molecular-species annotation; Silver = sum composition or partial structure; Bronze = lipid-class level; Unidentified = no structural annotation. Silver appears only where the release supports it (the two archaeal phyla, positive mode); negative mode has no Silver tier.
A7: Source: the strict biomarker set in annotation_evidence_pos.csv and annotation_evidence_neg.csv - the same features Figure 2 and Supplementary Figure 7 are built from. Per-phylum, per-tier counts reproduce annotation/tier_counts.csv exactly, and the totals match the release feature counts (11,371 POS, 5,697 NEG).
A9: This is a fresh strict discovery, NOT a relabel of the submitted table (which counted 10,454 POS / 5,741 NEG over the pre-correction 21 / 23 phyla). Relabelling was shown to be invalid: two of three merged units would have been overstated roughly threefold, because a biomarker is defined by contrast against a background and merging changes that background. The strict Streptophyta count (5,168 POS) versus a legacy land-plant sum of 1,554 shows why a fresh discovery, not a sum, is required.
A11: Kingdom labels use the locked policy's ecological_group naming (Viridiplantae, Protists). The two source files disagreed - the positive file already used these, the negative file still carried Plantae / Protozoa - and are reconciled here.
A13: Taxonomy release: ncbi-phylum-2026-08-04-v1 (locked). Producer: paper2_repro/scripts/build_table_s5_strict16.py

Sheet S5_Positive_mode
A1: Supplementary Table S5a. Positive-mode biomarker counts (11,371 biomarkers, 16 analysis phyla)
A2: Strict release biomarker set (indval_consensus + composite discovery), by annotation tier.
A4: Phylum | B4: Kingdom | C4: Gold | D4: Silver | E4: Bronze | F4: Unidentified | G4: Total | H4: Gold+Silver | I4: Annotated | J4: Annotated %
A5: Arthropoda | B5: Animalia | C5: 5 | D5: 0 | E5: 140 | F5: 237 | G5: 382 | H5: 5 | I5: 145 | J5: 38
A6: Mollusca | B6: Animalia | C6: 0 | D6: 0 | E6: 61 | F6: 394 | G6: 455 | H6: 0 | I6: 61 | J6: 13.4
A7: Nematoda | B7: Animalia | C7: 4 | D7: 0 | E7: 148 | F7: 270 | G7: 422 | H7: 4 | I7: 152 | J7: 36
A8: Methanobacteriota | B8: Archaea | C8: 213 | D8: 90 | E8: 164 | F8: 550 | G8: 1017 | H8: 303 | I8: 467 | J8: 45.9
A9: Thermoproteota | B9: Archaea | C9: 47 | D9: 29 | E9: 70 | F9: 170 | G9: 316 | H9: 76 | I9: 146 | J9: 46.2
A10: Actinomycetota | B10: Bacteria | C10: 63 | D10: 0 | E10: 117 | F10: 94 | G10: 274 | H10: 63 | I10: 180 | J10: 65.7
A11: Bacillota | B11: Bacteria | C11: 169 | D11: 0 | E11: 279 | F11: 573 | G11: 1021 | H11: 169 | I11: 448 | J11: 43.9
A12: Pseudomonadota | B12: Bacteria | C12: 103 | D12: 0 | E12: 135 | F12: 175 | G12: 413 | H12: 103 | I12: 238 | J12: 57.6
A13: Ascomycota | B13: Fungi | C13: 13 | D13: 0 | E13: 118 | F13: 130 | G13: 261 | H13: 13 | I13: 131 | J13: 50.2
A14: Basidiomycota | B14: Fungi | C14: 54 | D14: 0 | E14: 204 | F14: 183 | G14: 441 | H14: 54 | I14: 258 | J14: 58.5
A15: Mucoromycota | B15: Fungi | C15: 1 | D15: 0 | E15: 12 | F15: 19 | G15: 32 | H15: 1 | I15: 13 | J15: 40.6
A16: Discosea | B16: Protists | C16: 13 | D16: 0 | E16: 8 | F16: 14 | G16: 35 | H16: 13 | I16: 21 | J16: 60
... A20: Streptophyta | B20: Viridiplantae | C20: 827 | D20: 0 | E20: 2815 | F20: 1526 | G20: 5168 | H20: 827 | I20: 3642 | J20: 70.5
A21: TOTAL | C21: =SUM(C5:C20) | D21: =SUM(D5:D20) | E21: =SUM(E5:E20) | F21: =SUM(F5:F20) | G21: =SUM(G5:G20) | H21: =SUM(H5:H20) | I21: =SUM(I5:I20) | J21: =ROUND(100*I21/G21,1)

Sheet S5_Negative_mode
A1: Supplementary Table S5b. Negative-mode biomarker counts (5,697 biomarkers, 16 analysis phyla)
A2: Strict release biomarker set. Negative mode has no Silver tier.
A4: Phylum | B4: Kingdom | C4: Gold | D4: Silver | E4: Bronze | F4: Unidentified | G4: Total | H4: Gold+Silver | I4: Annotated | J4: Annotated %
A5: Arthropoda | B5: Animalia | C5: 50 | D5: 0 | E5: 191 | F5: 512 | G5: 753 | H5: 50 | I5: 241 | J5: 32
A6: Mollusca | B6: Animalia | C6: 8 | D6: 0 | E6: 57 | F6: 262 | G6: 327 | H6: 8 | I6: 65 | J6: 19.9
A7: Nematoda | B7: Animalia | C7: 6 | D7: 0 | E7: 58 | F7: 185 | G7: 249 | H7: 6 | I7: 64 | J7: 25.7
A8: Methanobacteriota | B8: Archaea | C8: 0 | D8: 0 | E8: 10 | F8: 8 | G8: 18 | H8: 0 | I8: 10 | J8: 55.6
A9: Thermoproteota | B9: Archaea | C9: 0 | D9: 0 | E9: 2 | F9: 1 | G9: 3 | H9: 0 | I9: 2 | J9: 66.7
A10: Actinomycetota | B10: Bacteria | C10: 11 | D10: 0 | E10: 4 | F10: 31 | G10: 46 | H10: 11 | I10: 15 | J10: 32.6
A11: Bacillota | B11: Bacteria | C11: 35 | D11: 0 | E11: 43 | F11: 168 | G11: 246 | H11: 35 | I11: 78 | J11: 31.7
A12: Pseudomonadota | B12: Bacteria | C12: 35 | D12: 0 | E12: 30 | F12: 100 | G12: 165 | H12: 35 | I12: 65 | J12: 39.4
A13: Ascomycota | B13: Fungi | C13: 172 | D13: 0 | E13: 328 | F13: 437 | G13: 937 | H13: 172 | I13: 500 | J13: 53.4
A14: Basidiomycota | B14: Fungi | C14: 20 | D14: 0 | E14: 62 | F14: 72 | G14: 154 | H14: 20 | I14: 82 | J14: 53.2
A15: Mucoromycota | B15: Fungi | C15: 3 | D15: 0 | E15: 5 | F15: 9 | G15: 17 | H15: 3 | I15: 8 | J15: 47.1
A16: Discosea | B16: Protists | C16: 0 | D16: 0 | E16: 1 | F16: 7 | G16: 8 | H16: 0 | I16: 1 | J16: 12.5
... A20: Streptophyta | B20: Viridiplantae | C20: 165 | D20: 0 | E20: 387 | F20: 905 | G20: 1457 | H20: 165 | I20: 552 | J20: 37.9
A21: TOTAL | C21: =SUM(C5:C20) | D21: =SUM(D5:D20) | E21: =SUM(E5:E20) | F21: =SUM(F5:F20) | G21: =SUM(G5:G20) | H21: =SUM(H5:H20) | I21: =SUM(I5:I20) | J21: =ROUND(100*I21/G21,1)

Sheet S6_Notes
A1: Supplementary Table S6. Literature-reported expected composition ranges by organism group
A3: Coarse expectations used as a plausibility reference for the corrected ClimGrass composition (Fig. 6a). Each range is anchored to the soil-biology literature.
A4: Caveat: these are order-of-magnitude expectations synthesised from the soil-biology literature on relative biomass/abundance; no single study reports a lipid-signal fraction per organism group for an entire soil food web. They serve as a coarse plausibility reference, not a quantitative ground truth.
A6: Supplementary references for Table S6 (not in main reference list):
A7: Bar-On, Y. M., Phillips, R. & Milo, R. (2018). The biomass distribution on Earth. PNAS 115, 6506-6511.
A8: Joergensen, R. G. & Wichern, F. (2008). Quantitative assessment of the fungal contribution to microbial tissue in soil. Soil Biology and Biochemistry 40, 2977-2991.
A9: Strickland, M. S. & Rousk, J. (2010). Considering fungal:bacterial dominance in soils. Soil Biology and Biochemistry 42, 1385-1395.
A10: Bates, S. T. et al. (2011). Examining the global distribution of dominant archaeal populations in soil. ISME Journal 5, 908-917.
A11: Jackson, R. B. et al. (1996). A global analysis of root distributions for terrestrial biomes. Oecologia 108, 389-411.
A12: Frozen 2026-06-09. Transcribed verbatim from soilmasst-v4_7-supplementary.md.
A14: Strict-16 update 2026-08-12: organism-group labels conformed to the locked ecological_group vocabulary in taxonomy_policy.json (release ncbi-phylum-2026-08-04-v1): Plantae -> Viridiplantae, Protozoa -> Protists. Ranges, bases, and references are unchanged from the frozen 2026-06-09 version; these expectations are literature-derived and are not affected by the taxonomy correction.
A16: Lipid-content conversion factors (new in strict-16 v2) — total lipid as % dry mass, ordinary states:
... A36: Strict-16 v2 update 2026-08-21: added lipid-content conversion factors (E3:F9) and lipid references (Notes rows 17-34). Biomass ranges unchanged. All values are total lipid %DM (gravimetric), not total fatty acids or PLFA-only.

Sheet S6_Table
A1: Supplementary Table S6. Literature-reported expected composition ranges by organism group
A3: Organism group | B3: Expected (%) | C3: Basis | D3: Key references | E3: Lipid content (% dry mass) | F3: Lipid content source
A4: Bacteria | B4: 35-50 | C4: Dominant prokaryotic biomass in temperate grassland topsoil | D4: Bar-On et al. 2018; Joergensen 2022; Frostegard et al. 2011; Delgado-Baquerizo et al. 2018 | E4: 7 | F4: Taipale et al. 2015 (7.3±0.8%); Beck et al. 2018
A5: Fungi | B5: 15-30 | C5: Fungal biomass 10-60% of microbial biomass in arable/grassland soils | D5: Joergensen & Wichern 2008; Strickland & Rousk 2010; Frostegard et al. 2011 | E5: 10 | F5: Jones 1969 (10-20%); Weete et al. 1985; Raju et al. 1976
A6: Viridiplantae | B6: 15-30 | C6: Root material + exudates; grasslands have high root:shoot allocation | D6: Jackson et al. 1996; Bardgett & van der Putten 2014 | E6: 2.5 | F6: Poorter & Bergkotte 1992 (roots 1.6-2.6%)
A7: Archaea | B7: 2-8 | C7: Archaea average approximately 2% of soil prokaryotes, mainly ammonia-oxidising Thaumarchaeota | D7: Bates et al. 2011; Leininger et al. 2006 | E7: 6 | F7: Kates et al. 1962 (~2%); Langworthy et al. 1974 (~2.5%); Ferrante et al. 1988 (~10%); midpoint 5-7% assumed
A8: Animalia | B8: 1-5 | C8: Soil meso/microfauna are a small fraction of soil biomass | D8: Bar-On et al. 2018; van den Hoogen et al. 2019 | E8: 18 | F8: Hutzell & Krusberg 1982 (19.6-22.1% nematodes); Convey 1992 (mites 10-15%)*; Dai et al. 2021; Kavle et al. 2023
A9: Protists | B9: <1 | C9: Protists a minor biomass fraction, difficult to resolve biochemically | D9: Geisen et al. 2018; Adl & Coleman 2005 | E9: 10 | F9: Bowers & Korn 1968 (Acanthamoeba ~10%); Finkel et al. 2016 (algae median 17-22%)*
A11: * Lipid content values are total solvent-extractable lipid as % dry mass for ordinary physiological states and are used as conversion factors (biomass = lipid signal / lipid content, renormalised). Mite value (10-15%) is the only direct %DM for mites; collembola/insect values higher. Algal median 17-22% is microalgae-specific; heterotrophic protists use Acanthamoeba 10%. See Notes for full citations.

Sheet S7_Notes
A1: Supplementary Table S7. Empirical lipid-class response factors (RIE) used in the ClimGrass quantification correction
A2: What this table is:
A3: Empirically measured relative ionization efficiencies (RIE), per lipid class and adduct, that the adopted ClimGrass decomposition pipeline uses to correct for differential lipid-class response under electrospray ionization. The correction divides each detected feature's intensity by its class/adduct RIE (expressed relative to LPE), so classes that ionize strongly (high RIE, e.g. PC, SM) are scaled down and classes that ionize weakly (low RIE, e.g. MG, DG, SQDG) are scaled toward a common LPE reference.
A4: Adopted pipeline configuration (Figure 5 v2, positive mode):
A5: IS normalization + RIE correction under Rule A + ArchLips archaeal restriction. Composition is read from a held-out mixture benchmark (marker-panel estimator as the provenance-of-signal readout; fc-weighted BC with rules as the living-community readout). The RIE correction uses the M+H and M+NH4 rows.
A6: How the applied factor is derived (Rule A calibration gate):
A7: 1. Mean RIE relative to LPE is taken across all measured standards within each (lipid class, adduct) group (framework/corrections.py: groupby(class, adduct).mean()).
A8: 2. Rule A calibration gate: a class is used for correction only if its mean RIE falls inside the trusted window [0.20, 100]. In-window classes are corrected by factor = 1 / RIE. Classes whose RIE falls outside the window (below 0.20 or above 100) are treated as UNCALIBRATED and left uncorrected (factor = 1.0).
A9: 3. This replaces the hard floor/ceiling clip used in the originally submitted Fig. 6a pipeline, which set out-of-range RIE to the 0.20 floor (5x amplification) or the 100 ceiling (0.01x suppression). Rule A applies no amplification to out-of-range classes at all.
A10: Why Rule A (Supplementary Method 8, revised):
A11: Even with a 0.20 floor, the lowest-RIE classes were amplified 5x, concentrating leverage in a handful of noise-level features (MG RIE 0.0005, DG 0.03) and previously flipping the published Actinomycetota drought direction. A 5x extrapolation of a standard whose ionization efficiency sits far outside the calibrated range is not trustworthy, so Rule A declines to correct those classes rather than amplifying them. This preserves the published treatment-effect directions while removing the floor-amplification artifact.
A12: Effect on this table: 16 of 57 (class, adduct) groups fall outside the window and are uncalibrated under Rule A (15 below 0.20, previously 5x; and LPC M+H above 100, previously 0.01x). The 41 in-window groups are unchanged (factor = 1 / RIE). The 'Uncapped factor' column shows the naive 1 / RIE that Rule A declines to apply.
... A17: Strict-16 rebuild 2026-08-12: rebuilt to document the Figure 5 v2 correction (Rule A) rather than the submitted hard-floor pipeline. The measured RIE values and log10(RIE) are unchanged and reproduce exactly from the 109-standard source (max |delta| 5e-15); only the out-of-range handling and the derived factor columns changed. RIE is a lipid-class property with no taxonomic content, so this table is otherwise unaffected by the strict-phyla correction.

Sheet S7_RIE_all_adducts
A1: Supplementary Table S7. Empirical response (RIE) factors - RIE all adducts
A2: RIE relative to LPE. Rule A calibration gate (Figure 5 v2): classes with RIE inside the trusted window [0.20, 100] are corrected by 1 / RIE; classes outside the window are treated as uncalibrated and left uncorrected (factor 1.0).
A3: Lipid class | B3: Adduct | C3: Ionization mode | D3: n standards averaged | E3: RIE relative to LPE | F3: log10(RIE) | G3: RIE in calibrated window [0.20, 100]? | H3: Correction status (Rule A) | I3: Applied correction factor | J3: Uncapped factor (1 / RIE)
A4: MG | B4: M+H | C4: Positive | D4: 1 | E4: 0.00048271681 | F4: -3.3163076 | G4: no | H4: uncalibrated | I4: 1 | J4: 2071.608
A5: SQDG | B5: M+H | C5: Positive | D5: 1 | E5: 0.00096542429 | F5: -3.0152818 | G5: no | H5: uncalibrated | I5: 1 | J5: 1035.814
A6: MGDG | B6: M+H | C6: Positive | D6: 1 | E6: 0.0025911255 | F6: -2.5865115 | G6: no | H6: uncalibrated | I6: 1 | J6: 385.93267
A7: TG | B7: M+H | C7: Positive | D7: 1 | E7: 0.0060515053 | F7: -2.2181366 | G7: no | H7: uncalibrated | I7: 1 | J7: 165.24814
A8: DG | B8: M+H | C8: Positive | D8: 2 | E8: 0.032342137 | F8: -1.4902313 | G8: no | H8: uncalibrated | I8: 1 | J8: 30.919417
A9: CE | B9: M+H | C9: Positive | D9: 1 | E9: 0.10554418 | F9: -0.97656569 | G9: no | H9: uncalibrated | I9: 1 | J9: 9.4747049
A10: PG | B10: M+H | C10: Positive | D10: 2 | E10: 0.12861743 | F10: -0.89070018 | G10: no | H10: uncalibrated | I10: 1 | J10: 7.7749962
A11: PI | B11: M+H | C11: Positive | D11: 2 | E11: 0.26375553 | F11: -0.57879842 | G11: yes | H11: calibrated | I11: 3.7913897 | J11: 3.7913897
A12: CERP | B12: M+H | C12: Positive | D12: 1 | E12: 0.44441883 | F12: -0.35220755 | G12: yes | H12: calibrated | I12: 2.2501297 | J12: 2.2501297
A13: LPA | B13: M+H | C13: Positive | D13: 1 | E13: 0.81163491 | F13: -0.090639284 | G13: yes | H13: calibrated | I13: 1.2320811 | J13: 1.2320811
A14: HEXCER | B14: M+H | C14: Positive | D14: 1 | E14: 1.4414195 | F14: 0.1587904 | G14: yes | H14: calibrated | I14: 0.69376055 | J14: 0.69376055
A15: CER | B15: M+H | C15: Positive | D15: 2 | E15: 3.7817541 | F15: 0.57769329 | G15: yes | H15: calibrated | I15: 0.26442756 | J15: 0.26442756
... A60: LPC | B60: M+HCOO | C60: Negative | D60: 4 | E60: 51.35105 | F60: 1.7105493 | G60: yes | H60: calibrated | I60: 0.019473799 | J60: 0.019473799
A62: Uncalibrated = mean RIE outside the trusted window [0.20, 100]; Rule A leaves these classes uncorrected (factor 1.0) rather than extrapolating. Uncapped factor = naive 1 / RIE, shown for reference.

Sheet S7_RIE_positive_mode
A1: Supplementary Table S7. Empirical response (RIE) factors - RIE positive mode
A2: RIE relative to LPE. Rule A calibration gate (Figure 5 v2): classes with RIE inside the trusted window [0.20, 100] are corrected by 1 / RIE; classes outside the window are treated as uncalibrated and left uncorrected (factor 1.0).
A3: Lipid class | B3: Adduct | C3: Ionization mode | D3: n standards averaged | E3: RIE relative to LPE | F3: log10(RIE) | G3: RIE in calibrated window [0.20, 100]? | H3: Correction status (Rule A) | I3: Applied correction factor | J3: Uncapped factor (1 / RIE)
A4: MG | B4: M+H | C4: Positive | D4: 1 | E4: 0.00048271681 | F4: -3.3163076 | G4: no | H4: uncalibrated | I4: 1 | J4: 2071.608
A5: SQDG | B5: M+H | C5: Positive | D5: 1 | E5: 0.00096542429 | F5: -3.0152818 | G5: no | H5: uncalibrated | I5: 1 | J5: 1035.814
A6: MGDG | B6: M+H | C6: Positive | D6: 1 | E6: 0.0025911255 | F6: -2.5865115 | G6: no | H6: uncalibrated | I6: 1 | J6: 385.93267
A7: TG | B7: M+H | C7: Positive | D7: 1 | E7: 0.0060515053 | F7: -2.2181366 | G7: no | H7: uncalibrated | I7: 1 | J7: 165.24814
A8: DG | B8: M+H | C8: Positive | D8: 2 | E8: 0.032342137 | F8: -1.4902313 | G8: no | H8: uncalibrated | I8: 1 | J8: 30.919417
A9: CE | B9: M+H | C9: Positive | D9: 1 | E9: 0.10554418 | F9: -0.97656569 | G9: no | H9: uncalibrated | I9: 1 | J9: 9.4747049
A10: PG | B10: M+H | C10: Positive | D10: 2 | E10: 0.12861743 | F10: -0.89070018 | G10: no | H10: uncalibrated | I10: 1 | J10: 7.7749962
A11: PI | B11: M+H | C11: Positive | D11: 2 | E11: 0.26375553 | F11: -0.57879842 | G11: yes | H11: calibrated | I11: 3.7913897 | J11: 3.7913897
A12: CERP | B12: M+H | C12: Positive | D12: 1 | E12: 0.44441883 | F12: -0.35220755 | G12: yes | H12: calibrated | I12: 2.2501297 | J12: 2.2501297
A13: LPA | B13: M+H | C13: Positive | D13: 1 | E13: 0.81163491 | F13: -0.090639284 | G13: yes | H13: calibrated | I13: 1.2320811 | J13: 1.2320811
A14: HEXCER | B14: M+H | C14: Positive | D14: 1 | E14: 1.4414195 | F14: 0.1587904 | G14: yes | H14: calibrated | I14: 0.69376055 | J14: 0.69376055
A15: CER | B15: M+H | C15: Positive | D15: 2 | E15: 3.7817541 | F15: 0.57769329 | G15: yes | H15: calibrated | I15: 0.26442756 | J15: 0.26442756
... A37: PA | B37: M+NH4 | C37: Positive | D37: 1 | E37: 47.315482 | F37: 1.6750033 | G37: yes | H37: calibrated | I37: 0.021134732 | J37: 0.021134732
A39: Uncalibrated = mean RIE outside the trusted window [0.20, 100]; Rule A leaves these classes uncorrected (factor 1.0) rather than extrapolating. Uncapped factor = naive 1 / RIE, shown for reference.

Sheet S8_Notes
A1: Supplementary Table S8. ClimGrass per-treatment composition (strict phyla, Figure 5 v2)
A2: Lipid-derived composition for the four ClimGrass treatments (ambient control, ambient + drought, future climate, future + drought; n = 3 each), from the Figure 5 v2 decomposition on the 16 strict analysis phyla.
A3: Primary composition = fold-change-weighted Bray-Curtis with hygiene rules (Rule A calibration gate, enriched-weight split, sqrt), the living-community estimate shown as the figure's bars. Marker-panel composition (the provenance-of-signal estimate, shown as the figure's diamonds) is given per sample in sheet S8e.
A4: Sheets: 'Kingdom_by_treatment' (S8a) and 'Phylum_by_treatment' (S8b) give per-treatment mean % and SD (n=3). 'Treatment_effects' (S8c) gives drought and climate contrasts from CLR-centred fingerprint-set permutation tests (400 stratified relabelings) with BH q, plus the pre-specified qSIP replication family. 'Per_sample_fcweighted' (S8d) and 'Per_sample_markerpanel' (S8e) give the 12 individual soil samples.
A5: Treatment contrasts are exploratory (n = 3 per treatment; n = 6 per side). Composition values are fractions of total decomposed signal; by-treatment sheets express them as percentages. Kingdom labels follow the locked ecological_group vocabulary (Viridiplantae, Protists).
A6: Headline drought result (qSIP replication): Pseudomonadota decreases under drought, observed log2FC -0.60, one-sided permutation p = 0.0025, BH q = 0.005 (family of 2). This is a pre-specified directional replication of Metze et al. 2023 qSIP predictions.
A7: Source: outputs/analysis/ncbi-phylum-2026-08-04-v1/climgrass/figure5_redesign_2026-08-08_v2_archlips/ (composition_fcweighted_by_sample.csv, composition_winner_by_sample.csv, r_render/data/kingdom_composition.csv, fingerprint_set_effects.csv, qsip_replication_test.csv). Producer: paper2_repro/scripts/build_table_s8_strict16.py.

Sheet S8_Kingdom_by_treatment
A1: Supplementary Table S8a. Kingdom composition by treatment (mean % +/- SD, n=3)
A2: Group | B2: Ambient_Control mean % | C2: Ambient_Control SD | D2: Ambient_Drought mean % | E2: Ambient_Drought SD | F2: Future_Control mean % | G2: Future_Control SD | H2: Future_Drought mean % | I2: Future_Drought SD | J2: Overall mean %
A3: Bacteria | B3: 37.74 | C3: 2.33 | D3: 38.64 | E3: 1.12 | F3: 38.22 | G3: 2.06 | H3: 38.29 | I3: 2.8 | J3: 38.22
A4: Archaea | B4: 6.22 | C4: 1.69 | D4: 4.42 | E4: 4.64 | F4: 5.29 | G4: 2.39 | H4: 6.22 | I4: 2.11 | J4: 5.54
A5: Fungi | B5: 28.95 | C5: 3.14 | D5: 25.58 | E5: 1.79 | F5: 28.09 | G5: 3.54 | H5: 28.69 | I5: 1.64 | J5: 27.83
A6: Viridiplantae | B6: 9.26 | C6: 1.72 | D6: 10.2 | E6: 1.32 | F6: 9.31 | G6: 2.2 | H6: 9.63 | I6: 1.51 | J6: 9.6
A7: Animalia | B7: 13.9 | C7: 0.25 | D7: 16.63 | E7: 2.58 | F7: 14.94 | G7: 1.38 | H7: 13.4 | I7: 0.75 | J7: 14.71
A8: Protists | B8: 3.94 | C8: 0.09 | D8: 4.54 | E8: 0.89 | F8: 4.16 | G8: 0.3 | H8: 3.78 | I8: 0.14 | J8: 4.11

Sheet S8_Phylum_by_treatment
A1: Supplementary Table S8b. Phylum composition by treatment (mean % +/- SD, n=3)
A2: Group | B2: Ambient_Control mean % | C2: Ambient_Control SD | D2: Ambient_Drought mean % | E2: Ambient_Drought SD | F2: Future_Control mean % | G2: Future_Control SD | H2: Future_Drought mean % | I2: Future_Drought SD | J2: Overall mean %
A3: Actinomycetota | B3: 18.82 | C3: 0.48 | D3: 19.9 | E3: 3.27 | F3: 19.1 | G3: 1.25 | H3: 22.9 | I3: 4.67 | J3: 20.18
A4: Bacillota | B4: 5.17 | C4: 0.11 | D4: 7.36 | E4: 1.26 | F4: 6.14 | G4: 0.45 | H4: 5.45 | I4: 0.71 | J4: 6.03
A5: Pseudomonadota | B5: 13.75 | C5: 1.94 | D5: 11.38 | E5: 1.23 | F5: 12.98 | G5: 2.11 | H5: 9.94 | I5: 2.2 | J5: 12.01
A6: Methanobacteriota | B6: 5.23 | C6: 1.62 | D6: 3.82 | E6: 3.86 | F6: 4.6 | G6: 2.04 | H6: 4.71 | I6: 1.83 | J6: 4.59
A7: Thermoproteota | B7: 0.99 | C7: 0.21 | D7: 0.6 | E7: 0.78 | F7: 0.68 | G7: 0.38 | H7: 1.51 | I7: 0.9 | J7: 0.95
A8: Ascomycota | B8: 6.45 | C8: 0.78 | D8: 8.58 | E8: 2.66 | F8: 8.1 | G8: 3 | H8: 7.66 | I8: 0.87 | J8: 7.7
A9: Basidiomycota | B9: 14.65 | C9: 3.35 | D9: 10.78 | E9: 2.04 | F9: 13.36 | G9: 1.74 | H9: 13.83 | I9: 0.84 | J9: 13.15
A10: Mucoromycota | B10: 7.84 | C10: 1.61 | D10: 6.22 | E10: 0.28 | F10: 6.63 | G10: 0.67 | H10: 7.21 | I10: 0.46 | J10: 6.98
A11: Chlorophyta | B11: 0.99 | C11: 0.08 | D11: 1.15 | E11: 0.2 | F11: 1.1 | G11: 0.11 | H11: 0.95 | I11: 0.08 | J11: 1.05
A12: Streptophyta | B12: 8.27 | C12: 1.76 | D12: 9.04 | E12: 1.13 | F12: 8.21 | G12: 2.09 | H12: 8.68 | I12: 1.46 | J12: 8.55
A13: Arthropoda | B13: 4.13 | C13: 0.18 | D13: 5.41 | E13: 1.18 | F13: 4.89 | G13: 0.1 | H13: 5.59 | I13: 1.03 | J13: 5.01
A14: Mollusca | B14: 9.35 | C14: 0.34 | D14: 10.39 | E14: 1.6 | F14: 9.57 | G14: 1.4 | H14: 7.2 | I14: 0.26 | J14: 9.13
... A18: Heterolobosea | B18: 1.59 | C18: 0.08 | D18: 2.17 | E18: 0.31 | F18: 1.58 | G18: 0.08 | H18: 1.75 | I18: 0.07 | J18: 1.77

Sheet S8_Treatment_effects
A1: Supplementary Table S8c. Treatment effects - CLR fingerprint-set permutation tests
A2: Per-phylum fingerprint-set effects for the drought and climate contrasts (400 stratified CLR relabelings). log2FC = set-mean log2 fold change; p_perm two-sided; p_one_sided in the observed direction; q = Benjamini-Hochberg within factor.
A3: Factor | B3: Phylum | C3: Kingdom | D3: n set features | E3: set-mean log2FC | F3: direction | G3: p_perm (2-sided) | H3: p one-sided | I3: q (BH)
A4: climate | B4: Actinomycetota | C4: Bacteria | D4: 45 | E4: -0.277 | F4: down | G4: 0.365 | H4: 0.1825 | I4: 0.9257
A5: climate | B5: Arthropoda | C5: Animalia | D5: 90 | E5: -0.017 | F5: down | G5: 0.805 | H5: 0.4025 | I5: 0.9257
A6: climate | B6: Ascomycota | C6: Fungi | D6: 64 | E6: 0.155 | F6: up | G6: 0.305 | H6: 0.1525 | I6: 0.9257
A7: climate | B7: Bacillota | C7: Bacteria | D7: 29 | E7: -0.072 | F7: down | G7: 0.485 | H7: 0.2425 | I7: 0.9257
A8: climate | B8: Basidiomycota | C8: Fungi | D8: 126 | E8: 0.066 | F8: up | G8: 0.605 | H8: 0.3025 | I8: 0.9257
A9: climate | B9: Chlorophyta | C9: Viridiplantae | D9: 115 | E9: -0.084 | F9: down | G9: 0.475 | H9: 0.2375 | I9: 0.9257
A10: climate | B10: Discosea | C10: Protists | D10: 52 | E10: 0.035 | F10: up | G10: 0.9 | H10: 0.5525 | I10: 0.935
A11: climate | B11: Evosea | C11: Protists | D11: 54 | E11: -0.009 | F11: down | G11: 0.695 | H11: 0.3475 | I11: 0.9257
A12: climate | B12: Heterolobosea | C12: Protists | D12: 86 | E12: -0.144 | F12: down | G12: 0.55 | H12: 0.275 | I12: 0.9257
A13: climate | B13: Methanobacteriota | C13: Archaea | D13: 22 | E13: 0.049 | F13: up | G13: 0.935 | H13: 0.4675 | I13: 0.935
A14: climate | B14: Mollusca | C14: Animalia | D14: 46 | E14: -0.08 | F14: down | G14: 0.81 | H14: 0.405 | I14: 0.9257
A15: climate | B15: Mucoromycota | C15: Fungi | D15: 59 | E15: 0.046 | F15: up | G15: 0.575 | H15: 0.2875 | I15: 0.9257
... A35: drought | B35: Thermoproteota | C35: Archaea | D35: 27 | E35: -0.065 | F35: down | G35: 0.87 | H35: 0.5675 | I35: 0.97
A37: qSIP replication family (pre-specified directional test, Metze et al. 2023)
A38: Phylum | B38: predicted direction | C38: observed log2FC | D38: p one-sided | E38: q (BH, family=2)
A39: Pseudomonadota | B39: decrease | C39: -0.595 | D39: 0.0025 | E39: 0.005
A40: Actinomycetota | B40: increase | C40: 0.383 | D40: 0.2025 | E40: 0.2025

Sheet S8_Per_sample_fcweighted
A1: Supplementary Table S8d. Per-sample composition - fc-weighted (primary), fractions 0-1
A2: column_name | B2: treatment | C2: climate | D2: drought | E2: Bacteria | F2: Archaea | G2: Fungi | H2: Viridiplantae | I2: Animalia | J2: Protists | K2: Actinomycetota | L2: Bacillota | M2: Pseudomonadota | N2: Methanobacteriota | O2: Thermoproteota | P2: Ascomycota | Q2: Basidiomycota | R2: Mucoromycota | S2: Chlorophyta | T2: Streptophyta | U2: Arthropoda | V2: Mollusca | W2: Nematoda | X2: Discosea | Y2: Evosea | Z2: Heterolobosea | AA2: Sum check
A3: OE12-3-49POS.raw Peak area | B3: Ambient_Drought | C3: Ambient | D3: Drought | E3: 0.39513746 | F3: 0.016594615 | G3: 0.27619586 | H3: 0.10934164 | I3: 0.15698847 | J3: 0.04574195 | K3: 0.20772223 | L3: 0.069051823 | M3: 0.11836341 | N3: 0.014928235 | O3: 0.0016663807 | P3: 0.098695456 | Q3: 0.11700432 | R3: 0.060496085 | S3: 0.01203179 | T3: 0.097309855 | U3: 0.054752393 | V3: 0.090232484 | W3: 0.012003595 | X3: 0.0073986299 | Y3: 0.015400152 | Z3: 0.022943168 | AA3: =SUM(K3:Z3)
